<mujoco model="bruce">
    <compiler angle="radian" meshdir="../meshes" autolimits="true"/>
    <size njmax="500" nconmax="100" />
    <asset>
        <mesh name="base_link" file="base_link.STL"/>
        <mesh name="hip_yaw_link_r" file="hip_yaw_link_r.STL"/>
        <mesh name="hip_roll_link_r" file="hip_roll_link_r.STL"/>
        <mesh name="hip_pitch_link_r" file="hip_pitch_link_r.STL"/>
        <mesh name="knee_pitch_link_r" file="knee_pitch_link_r.STL"/>
        <mesh name="ankle_pitch_link_r" file="ankle_pitch_link_r.STL"/>
        <mesh name="hip_yaw_link_l" file="hip_yaw_link_l.STL"/>
        <mesh name="hip_roll_link_l" file="hip_roll_link_l.STL"/>
        <mesh name="hip_pitch_link_l" file="hip_pitch_link_l.STL"/>
        <mesh name="knee_pitch_link_l" file="knee_pitch_link_l.STL"/>
        <mesh name="ankle_pitch_link_l" file="ankle_pitch_link_l.STL"/>
        <mesh name="shoulder_pitch_link_r" file="shoulder_pitch_link_r.STL"/>
        <mesh name="shoulder_roll_link_r" file="shoulder_roll_link_r.STL"/>
        <mesh name="elbow_pitch_link_r" file="elbow_pitch_link_r.STL"/>
        <mesh name="shoulder_pitch_link_l" file="shoulder_pitch_link_l.STL"/>
        <mesh name="shoulder_roll_link_l" file="shoulder_roll_link_l.STL"/>
        <mesh name="elbow_pitch_link_l" file="elbow_pitch_link_l.STL"/>
    </asset>
    <worldbody>
        <body name="base_link" pos="0 0 0.47" euler='0 0.05 0'>
            <freejoint/>
            <inertial pos="0.02259605 -0.00011305 0.06140054" mass="1.4" diaginertia="0.0133543 0.01023631 0.005471"/>
            <geom type="mesh" rgba="0.870588 0.811765 0.764706 1" mesh="base_link" />
            <site name='imu' size='0.01' pos='0.0 0 0.0'/>
            <!-- ARM -->
            <geom pos="0.029216 -0.12375 0.152985" quat="0.620545 0.620545 -0.339005 0.339005" type="mesh" rgba="0.2 0.2 0.2 1" mesh="shoulder_pitch_link_r" />
            <geom pos="0.029216 -0.12375 0.152985" quat="-0.475932 0.105751 -0.871188 0.0577721" type="mesh" rgba="0 0 0 1" mesh="shoulder_roll_link_r" />
            <geom pos="-0.0260507 -0.156023 0.0576581" quat="-0.755321 -0.591798 -0.221617 0.173638" type="mesh" rgba="1 0.423529 0.0392157 1" mesh="elbow_pitch_link_r" />
            <geom pos="0.029216 0.12375 0.152985" quat="0.336393 -0.336393 0.621964 0.621964" type="mesh" rgba="0.2 0.2 0.2 1" mesh="shoulder_pitch_link_l" />
            <geom pos="0.029216 0.12375 0.152985" quat="0.472266 0.105993 0.873181 0.057327" type="mesh" rgba="0 0 0 1" mesh="shoulder_roll_link_l" />
            <geom pos="-0.0268502 0.156023 0.0581261" quat="0.754383 -0.591063 0.22479 0.176125" type="mesh" rgba="1 0.423529 0.0392157 1" mesh="elbow_pitch_link_l" />
             <!-- RIGHT LEG -->
            <body name="hip_yaw_link_r" pos="0.029216 -0.0758557 -0.039765" quat="0.707107 0 0 -0.707107">
                <inertial pos="2.71e-06 -0.00024824 0.00522427" quat="0.517691 0.482114 0.518083 0.480784" mass="0.637563" diaginertia="0.0016174 0.00152078 0.000485406" />
                <joint name="hip_yaw_r" pos="0 0 0" axis="0 0 1" limited="true" range="-3.1415 3.1415"/>
                <geom type="mesh" rgba="1 0.423529 0.0392157 1" mesh="hip_yaw_link_r" contype="0" conaffinity="0"/>
                <body name="hip_pitch_link_r" pos="0 0 0" quat="0.5 -0.5 0.5 0.5">
                    <inertial pos="-1.51e-07 0 6.88e-06" mass="0.05" diaginertia="1e-05 1e-05 1e-05"/>
                    <joint name="hip_pitch_r" pos="0 0 0" axis="0 0 1" limited="true" range="-3.1415 3.1415"/>
                    <geom type="mesh" rgba="1 0.423529 0.0392157 1" mesh="hip_roll_link_r" contype="0" conaffinity="0"/>
                    <body name="hip_roll_link_r" pos="0 0 0" quat="0.707107 0.707107 0 0">
                        <inertial pos="0.140714 -0.0086817 0.00167429" quat="-0.0210718 0.710934 0.00543456 0.702922" mass="0.72849" diaginertia="0.0181996 0.0179488 0.000479326" />
                        <joint name="hip_roll_r" pos="0 0 0" axis="0 0 1" limited="true" range="-3.1415 3.1415" />
                        <geom type="mesh" rgba="0.2 0.2 0.2 1" mesh="hip_pitch_link_r"/>
                        <body name="knee_pitch_link_r" pos="0.204949 0 0">
                            <inertial pos="0.0729308 0.0174645 0.00216432" quat="-0.0124752 0.71085 -0.0538621 0.701167" mass="0.0956654" diaginertia="0.00108397 0.00102192 0.000106307" />
                            <joint name="knee_pitch_r" pos="0 0 0" axis="0 0 1" limited="true" range="-3.1415 3.1415"/>
                            <geom type="mesh" rgba="0 0 0 1" mesh="knee_pitch_link_r"/>
                            <body name="ankle_pitch_link_r" pos="0.199881 0 0">
                                <inertial pos="0.0120775 0.0019746 0.00029511" quat="0.443128 0.545146 -0.456612 0.545855" mass="0.0276265" diaginertia="2.58838e-05 2.09859e-05 5.64035e-06" />
                                <joint name="ankle_pitch_r" pos="0 0 0" axis="0 0 1" limited="true" range="-3.1415 3.1415"/>
                                <geom type="mesh" rgba="1 0.423529 0.0392157 1" mesh="ankle_pitch_link_r"/>
                            </body>
                        </body>
                    </body>
                </body>
            </body>
             <!-- LEFT LEG -->
            <body name="hip_yaw_link_l" pos="0.029216 0.0758557 -0.039765" quat="0.707107 0 0 -0.707107">
                <inertial pos="0 -0.00020849 0.00528032" quat="0.518836 0.480432 0.518756 0.480506" mass="0.637386" diaginertia="0.00161868 0.00152047 0.0004852" />
                <joint name="hip_yaw_l" pos="0 0 0" axis="0 0 1" limited="true" range="-3.1415 3.1415" />
                <geom type="mesh" rgba="1 0.423529 0.0392157 1" mesh="hip_yaw_link_l"  contype="0" conaffinity="0"/>
                <body name="hip_pitch_link_l" pos="0 0 0" quat="0.500001 -0.499999 0.500001 0.499999">
                    <inertial pos="-1.51e-07 0 6.88e-06" mass="0.05" diaginertia="1e-05 1e-05 1e-05" />
                    <joint name="hip_pitch_l" pos="0 0 0" axis="0 0 1" limited="true" range="-3.1415 3.1415" />
                    <geom type="mesh" rgba="1 0.423529 0.0392157 1" mesh="hip_roll_link_l"  contype="0" conaffinity="0"/>
                    <body name="hip_roll_link_l" pos="0 0 0" quat="0.707107 0.707107 0 0">
                        <inertial pos="0.142447 -0.00832054 0.00049317" quat="-0.002203 0.702817 0.024599 0.710942" mass="0.720628" diaginertia="0.018195 0.0179541 0.000461885" />
                        <joint name="hip_roll_l" pos="0 0 0" axis="0 0 1" limited="true" range="-3.1415 3.1415" />
                        <geom type="mesh" rgba="0.2 0.2 0.2 1" mesh="hip_pitch_link_l" />
                        <body name="knee_pitch_link_l" pos="0.204949 0 0">
                            <inertial pos="0.0730996 0.0178102 -0.00219767" quat="0.0505999 0.70058 0.00930476 0.711716" mass="0.0952654" diaginertia="0.00107995 0.00101966 0.000104635" />
                            <joint name="knee_pitch_l" pos="0 0 0" axis="0 0 1" limited="true" range="-3.1415 3.1415" />
                            <geom type="mesh" rgba="0 0 0 1" mesh="knee_pitch_link_l" />
                            <body name="ankle_pitch_link_l" pos="0.199881 0 0">
                                <inertial pos="0.0123398 0.00253004 -0.00030441" quat="0.455603 0.546571 -0.442281 0.545962" mass="0.0274829" diaginertia="2.60237e-05 2.09939e-05 5.69233e-06" />
                                <joint name="ankle_pitch_l" pos="0 0 0" axis="0 0 1" limited="true" range="-3.1415 3.1415" />
                                <geom type="mesh" rgba="1 0.423529 0.0392157 1" mesh="ankle_pitch_link_l" />
                            </body>
                        </body>
                    </body>
                </body>
            </body>
        </body>
    </worldbody>
    <actuator>
    <motor name="hip_yaw_r" joint='hip_yaw_r' gear="1 0 0 0 0 0" ctrlrange='-200 200'/>
    <motor name="hip_pitch_r" joint='hip_pitch_r' gear="1 0 0 0 0 0" ctrlrange='-200 200'/>
    <motor name="hip_roll_r" joint='hip_roll_r' gear="1 0 0 0 0 0" ctrlrange='-200 200'/>
    <motor name="knee_pitch_r" joint='knee_pitch_r' gear="1 0 0 0 0 0" ctrlrange='-200 200'/>
    <motor name="ankle_pitch_r" joint='ankle_pitch_r' gear="1 0 0 0 0 0" ctrlrange='-200 200'/>

    <motor name="hip_yaw_l" joint='hip_yaw_l' gear="1 0 0 0 0 0" ctrlrange='-200 200'/>
    <motor name="hip_pitch_l" joint='hip_pitch_l' gear="1 0 0 0 0 0" ctrlrange='-200 200'/>
    <motor name="hip_roll_l" joint='hip_roll_l' gear="1 0 0 0 0 0" ctrlrange='-200 200'/>
    <motor name="knee_pitch_l" joint='knee_pitch_l' gear="1 0 0 0 0 0" ctrlrange='-200 200'/>
    <motor name="ankle_pitch_l" joint='ankle_pitch_l' gear="1 0 0 0 0 0" ctrlrange='-200 200'/>
  </actuator>
    <sensor>
        <actuatorpos name='hip_yaw_r_p'  actuator='hip_yaw_r' user='13'/>
        <actuatorpos name='hip_pitch_r_p'  actuator='hip_pitch_r' user='13'/>
        <actuatorpos name='hip_roll_r_p'  actuator='hip_roll_r' user='13'/>
        <actuatorpos name='knee_pitch_r_p'  actuator='knee_pitch_r' user='13'/>
        <actuatorpos name='ankle_pitch_r_p'  actuator='ankle_pitch_r' user='13'/>
        <actuatorpos name='hip_yaw_l_p'  actuator='hip_yaw_l' user='13'/>
        <actuatorpos name='hip_roll_l_p'  actuator='hip_roll_l' user='13'/>
        <actuatorpos name='hip_pitch_l_p'  actuator='hip_pitch_l' user='13'/>
        <actuatorpos name='knee_pitch_l_p'  actuator='knee_pitch_l' user='13'/>
        <actuatorpos name='ankle_pitch_l_p'  actuator='ankle_pitch_l' user='13'/>
        

        <actuatorvel name='hip_yaw_r_v'  actuator='hip_yaw_r' user='13'/>
        <actuatorvel name='hip_pitch_r_v'  actuator='hip_pitch_r' user='13'/>
        <actuatorvel name='hip_roll_r_v'  actuator='hip_roll_r' user='13'/>
        <actuatorvel name='knee_pitch_r_v'  actuator='knee_pitch_r' user='13'/>
        <actuatorvel name='ankle_pitch_r_v'  actuator='ankle_pitch_r' user='13'/>
        <actuatorvel name='hip_yaw_l_v'  actuator='hip_yaw_l' user='13'/>
        <actuatorvel name='hip_roll_l_v'  actuator='hip_roll_l' user='13'/>
        <actuatorvel name='hip_pitch_l_v'  actuator='hip_pitch_l' user='13'/>
        <actuatorvel name='knee_pitch_l_v'  actuator='knee_pitch_l' user='13'/>
        <actuatorvel name='ankle_pitch_l_v'  actuator='ankle_pitch_l' user='13'/>
        

        <actuatorfrc name='hip_yaw_r_f'  actuator='hip_yaw_r' user='13' noise='1e-3'/>
        <actuatorfrc name='hip_pitch_r_f'  actuator='hip_pitch_r' user='13' noise='1e-3'/>
        <actuatorfrc name='hip_roll_r_f'  actuator='hip_roll_r' user='13' noise='1e-3'/>
        <actuatorfrc name='knee_pitch_r_f'  actuator='knee_pitch_r' user='13' noise='1e-3'/>
        <actuatorfrc name='ankle_pitch_r_f'  actuator='ankle_pitch_r' user='13' noise='1e-3'/>
        <actuatorfrc name='hip_yaw_l_f'  actuator='hip_yaw_l' user='13' noise='1e-3'/>
        <actuatorfrc name='hip_roll_l_f'  actuator='hip_roll_l' user='13' noise='1e-3'/>
        <actuatorfrc name='hip_pitch_l_f'  actuator='hip_pitch_l' user='13' noise='1e-3'/>
        <actuatorfrc name='knee_pitch_l_f'  actuator='knee_pitch_l' user='13' noise='1e-3'/>
        <actuatorfrc name='ankle_pitch_l_f'  actuator='ankle_pitch_l' user='13' noise='1e-3'/>
        

        <framequat     name='orientation' objtype='site' noise='0.001' objname='imu'/>
        <framepos     name='position' objtype='site' noise='0.001' objname='imu'/>
        <gyro          name='angular-velocity'    site='imu' noise='0.005' cutoff='34.9'/>
        <velocimeter   name='linear-velocity'     site='imu' noise='0.001' cutoff='30'/>
        <accelerometer name='linear-acceleration' site='imu' noise='0.005' cutoff='157'/>
        <magnetometer  name='magnetometer'        site='imu'/>
    </sensor>
</mujoco>
